<?xml version="1.0"?>
<robot xmlns:xacro="http://www.ros.org/wiki/xacro" >

    <material name="white">
        <color rgba="1 1 1 1" />
    </material>

    <material name="orange">
        <color rgba="1 0.3 0.1 1"/>
    </material>

    <material name="blue">
        <color rgba="0.2 0.2 1 1"/>
    </material>

    <material name="black">
        <color rgba="0 0 0 1"/>
    </material>

    <material name="red">
        <color rgba="1 0 0 1"/>
    </material>
    
    <material name="green">
        <color rgba="0 1 0 1" />
    </material>

    <material name="gray">
        <color rgba="0.5 0.5 0.5 1" />
    </material>

    <material name="pink">
        <color rgba="1 0.4 0.7 1" />
    </material>


    <!-- BASE LINK -->

    <link name="base_link">
    </link>

    <!-- BASE_FOOTPRINT LINK -->
    <joint name="base_footprint_joint" type="fixed">
        <parent link="base_link"/>
        <child link="base_footprint"/>
        <origin xyz="0 0 0" rpy="0 0 0"/>
    </joint>

    <link name="base_footprint">
    </link>

    <joint name="chassis_joint" type="fixed">
        <parent link="base_link"/>
        <child link="chassis"/>
        <origin xyz="0 0 0"/>
    </joint>

    <!-- Chassis Link -->
    <link name="chassis">
        <visual>
            <origin xyz="0 0 0.13" rpy="0 0 0"/>
            <geometry>
                <box size="0.451 0.451 0.18"/>
                <!-- Hole geometry -->
                <cylinder length="0.15" radius="0.075"/>
            </geometry>
            <material name="pink"/>
        </visual>
        <collision>
            <origin xyz="0 0 0.13" rpy="0 0 0"/>
            <geometry>
                <box size="0.451 0.451 0.18"/>
                <!-- Hole geometry -->
                <cylinder length="0.15" radius="0.075"/>
            </geometry>
        </collision>
        <xacro:inertial_box mass="200.0" x="0.451" y="0.451" z="0.18">
            <origin xyz="0 0 0.13" rpy="0 0 0"/>
        </xacro:inertial_box>
    </link>
    <gazebo reference="chassis">
        <material>Gazebo/Wood   </material>
    </gazebo>

    <!-- Wheel Link -->
    <link name="front_left_wheel">
        <visual>
            <geometry>
                <cylinder length="0.04" radius="0.08" />
            </geometry>
            <material name="blue"/>
        </visual>
        <collision>
            <geometry>
                <cylinder length="0.04" radius="0.08" />
            </geometry>
        </collision>
        <xacro:inertial_cylinder mass="0.1" length="0.04" radius="0.08">
            <origin xyz="0 0 0" rpy="0 0 0"/>
        </xacro:inertial_cylinder>
    </link>
    <gazebo reference="front_left_wheel">
        <material>Gazebo/CloudySky </material>
    </gazebo>

    <link name="front_right_wheel">
        <visual>
            <geometry>
                <cylinder length="0.04" radius="0.08" />
            </geometry>
            <material name="red"/>
        </visual>
        <collision>
            <geometry>
                <cylinder length="0.04" radius="0.08" />
            </geometry>
        </collision>
        <xacro:inertial_cylinder mass="0.1" length="0.04" radius="0.08">
            <origin xyz="0 0 0" rpy="0 0 0"/>
        </xacro:inertial_cylinder>
    </link>
    <gazebo reference="front_right_wheel">
        <material>Gazebo/CloudySky </material>
    </gazebo>

    <link name="back_left_wheel">
        <visual>
            <geometry>
                <cylinder length="0.04" radius="0.08" />
            </geometry>
            <material name="orange"/>
        </visual>
        <collision>
            <geometry>
                <cylinder length="0.04" radius="0.08" />
            </geometry>
        </collision>
        <xacro:inertial_cylinder mass="0.1" length="0.04" radius="0.08">
            <origin xyz="0 0 0" rpy="0 0 0"/>
        </xacro:inertial_cylinder>
    </link>
    <gazebo reference="back_left_wheel">
        <material>Gazebo/CloudySky </material>
    </gazebo>

    <link name="back_right_wheel">
        <visual>
            <geometry>
                <cylinder length="0.04" radius="0.08" />
            </geometry>
            <material name="green"/>
        </visual>
        <collision>
            <geometry>
                <cylinder length="0.04" radius="0.08" />
            </geometry>
        </collision>
        <xacro:inertial_cylinder mass="0.1" length="0.04" radius="0.08">
            <origin xyz="0 0 0" rpy="0 0 0"/>
        </xacro:inertial_cylinder>
    </link>
    <gazebo reference="back_right_wheel">
        <material>Gazebo/CloudySky </material>
    </gazebo>

    <!-- Wheel Joint -->
    <!-- FRONT LEFT WHEEL -->
    <joint name="front_left_wheel_joint" type="continuous">
        <parent link="base_link"/>
        <child link="front_left_wheel"/>
        <origin xyz="0.165 0.205 0" rpy="-${pi/2} 0 0"/>
        <axis xyz="0 0 1"/>
    </joint>

    <!-- FRONT RIGHT WHEEL -->
    <joint name="front_right_wheel_joint" type="continuous">
        <parent link="base_link"/>
        <child link="front_right_wheel"/>
        <origin xyz="0.165 -0.205 0" rpy="${pi/2} 0 0"/>
        <axis xyz="0 0 -1"/>
    </joint>


    <!-- BACK LEFT WHEEL -->
    <joint name="back_left_wheel_joint" type="continuous">
        <parent link="base_link"/>
        <child link="back_left_wheel"/>
        <origin xyz="-0.165 0.205 0" rpy="-${pi/2} 0 0"/>
        <axis xyz="0 0 1"/>
    </joint>


    <!-- BACK RIGHT WHEEL -->
    <joint name="back_right_wheel_joint" type="continuous">
        <parent link="base_link"/>
        <child link="back_right_wheel"/>
        <origin xyz="-0.165 -0.205 0" rpy="${pi/2} 0 0"/>
        <axis xyz="0 0 -1"/>
    </joint>


</robot>